{
  "schema_version": "1.4.0",
  "id": "GHSA-rchv-vfvq-x3hp",
  "modified": "2022-05-24T16:56:29Z",
  "published": "2022-05-24T16:56:29Z",
  "aliases": [
    "CVE-2019-15032"
  ],
  "details": "Pydio 6.0.8 mishandles error reporting when a directory allows unauthenticated uploads, and the remote-upload option is used with the http://localhost:22 URL. The attacker can obtain sensitive information such as the name of the user who created that directory and other internal server information.",
  "severity": [],
  "affected": [],
  "references": [
    {
      "type": "ADVISORY",
      "url": "https://nvd.nist.gov/vuln/detail/CVE-2019-15032"
    },
    {
      "type": "WEB",
      "url": "https://heitorgouvea.me/2019/09/17/CVE-2019-15032"
    },
    {
      "type": "WEB",
      "url": "https://pydio.com"
    },
    {
      "type": "WEB",
      "url": "https://sourceforge.net/projects/ajaxplorer/files/pydio/stable-channel"
    }
  ],
  "database_specific": {
    "cwe_ids": [],
    "severity": "MODERATE",
    "github_reviewed": false,
    "github_reviewed_at": null,
    "nvd_published_at": "2019-09-19T17:15:00Z"
  }
}