{
  "schema_version": "1.4.0",
  "id": "GHSA-3rjp-hfjx-9689",
  "modified": "2022-10-31T19:00:32Z",
  "published": "2022-05-24T17:05:00Z",
  "aliases": [
    "CVE-2019-19950"
  ],
  "details": "In GraphicsMagick 1.4 snapshot-20190403 Q8, there is a use-after-free in ThrowException and ThrowLoggedException of magick/error.c.",
  "severity": [
    {
      "type": "CVSS_V3",
      "score": "CVSS:3.1/AV:N/AC:L/PR:N/UI:N/S:U/C:H/I:H/A:H"
    }
  ],
  "affected": [],
  "references": [
    {
      "type": "ADVISORY",
      "url": "https://nvd.nist.gov/vuln/detail/CVE-2019-19950"
    },
    {
      "type": "WEB",
      "url": "https://lists.debian.org/debian-lts-announce/2020/01/msg00029.html"
    },
    {
      "type": "WEB",
      "url": "https://sourceforge.net/p/graphicsmagick/bugs/603"
    },
    {
      "type": "WEB",
      "url": "https://www.debian.org/security/2020/dsa-4640"
    },
    {
      "type": "WEB",
      "url": "http://hg.graphicsmagick.org/hg/GraphicsMagick/rev/44ab7f6c20b4"
    },
    {
      "type": "WEB",
      "url": "http://lists.opensuse.org/opensuse-security-announce/2020-01/msg00026.html"
    },
    {
      "type": "WEB",
      "url": "http://lists.opensuse.org/opensuse-security-announce/2020-01/msg00064.html"
    }
  ],
  "database_specific": {
    "cwe_ids": [
      "CWE-416"
    ],
    "severity": "HIGH",
    "github_reviewed": false,
    "github_reviewed_at": null,
    "nvd_published_at": "2019-12-24T01:15:00Z"
  }
}